<?xml version="1.0"?>
<robot name="vicharaka-rover"
  xmlns:xacro="http://ros.org/wiki/xacro">

    <xacro:macro name="inertial_sphere" params="mass radius *origin">
        <inertial>
            <xacro:insert_block name="origin"/>
            <mass value="${mass}" />
            <inertia ixx="${(2/5) * mass * (radius*radius)}" ixy="0.0" ixz="0.0"
                    iyy="${(2/5) * mass * (radius*radius)}" iyz="0.0"
                    izz="${(2/5) * mass * (radius*radius)}" />
        </inertial>
    </xacro:macro>  


    <xacro:macro name="inertial_box" params="mass x y z *origin">
        <inertial>
            <xacro:insert_block name="origin"/>
            <mass value="${mass}" />
            <inertia ixx="${(1/12) * mass * (y*y+z*z)}" ixy="0.0" ixz="0.0"
                    iyy="${(1/12) * mass * (x*x+z*z)}" iyz="0.0"
                    izz="${(1/12) * mass * (x*x+y*y)}" />
        </inertial>
    </xacro:macro>


    <xacro:macro name="inertial_cylinder" params="mass length radius *origin">
        <inertial>
            <xacro:insert_block name="origin"/>
            <mass value="${mass}" />
            <inertia ixx="${(1/12) * mass * (3*radius*radius + length*length)}" ixy="0.0" ixz="0.0"
                    iyy="${(1/12) * mass * (3*radius*radius + length*length)}" iyz="0.0"
                    izz="${(1/2) * mass * (radius*radius)}" />
        </inertial>
    </xacro:macro>

<xacro:property name="chassis_length" value="0.703"/>
    <xacro:property name="chassis_width" value="0.545"/>
    <xacro:property name="chassis_height" value="0.17"/>
    <xacro:property name="chassis_mass" value="4.0"/>
    <xacro:property name="wheel_radius" value="0.192"/>
    <xacro:property name="wheel_thickness" value="0.072"/>
    <xacro:property name="wheel_mass" value="0.788"/>
    <xacro:property name="wheel_offset_x" value="0.226"/>
    <xacro:property name="wheel_offset_y" value="0.1485"/>
    <xacro:property name="wheel_offset_z" value="0.01"/>

    <material name="white">
        <color rgba="1 1 1 1" />
    </material>

    <material name="orange">
        <color rgba="1 0.3 0.1 1"/>
    </material>

    <material name="blue">
        <color rgba="0.2 0.2 1 1"/>
    </material>

    <material name="black">
        <color rgba="0 0 0 1"/>
    </material>

    <material name="red">
        <color rgba="1 0 0 1"/>
    </material>

    
    <link name="base_link">
    </link>

    <link name="base_footprint">
    </link>

    <joint name="base_footprint_joint" type="fixed">
        <parent link="base_footprint"/>
        <child link="base_link"/>
        <origin xyz="0 0 0.5" rpy="0 0 0"/>
    </joint>


    <link name="chassis">
        <visual>
            <geometry>
                <box size="0.6 0.4 0.2"/>
            </geometry>
            <origin xyz="0 0 0" rpy="0 0 0"/>
            <material name="blue"/>
        </visual>
    </link>

    <joint name="chassis_joint" type="fixed">
        <parent link="base_link"/>
        <child link="chassis"/>
        <origin xyz="0 0 0" rpy="0 0 0"/>
    </joint>

    <link name="left_diff_link" />

    <link name="l_rod_1">
        <visual>
            <geometry>
                <box size="0.03 0.03 0.64"/>
            </geometry>
            <material name="red"/>
            <origin xyz="0 0 -0.32" rpy="0 0 0"/>
        </visual>
    </link>

    
    <link name="l_rod_2">
        <visual>
            <geometry>
                <box size="0.03 0.03 0.28"/>
            </geometry>
            <material name="red"/>

            <origin xyz="0 0 -0.14" rpy="0 0 0"/>
        </visual>
    </link>

    <link name="left_rod2_sub_link" />

    <link name="l_rod_3">
        <visual>
            <geometry>
                <box size="0.03 0.03 0.36"/>
            </geometry>
            <material name="red"/>
            <origin xyz="0 0 -0.18" rpy="0 0 0"/>
        </visual>
    </link>
    <link name="l_rod_4">
        <visual>
            <geometry>
                <box size="0.03 0.03 0.36"/>
            </geometry>
            <material name="red"/>
            <origin xyz="0 0 -0.18" rpy="0 0 0"/>
        </visual>
    </link>


    <link name="right_diff_link" />

    <link name="r_rod_1">
        <visual>
            <geometry>
                <box size="0.03 0.03 0.64"/>
            </geometry>
            <material name="red"/>
            <origin xyz="0 0 -0.32" rpy="0 0 0"/>
        </visual>
    </link>

    <link name="r_rod_2">
        <visual>
            <geometry>
                <box size="0.03 0.03 0.28"/>
            </geometry>
            <material name="red"/>

            <origin xyz="0 0 -0.14" rpy="0 0 0"/>
        </visual>
    </link>

    <link name="right_rod2_sub_link" />

    <link name="r_rod_3">
        <visual>
            <geometry>
                <box size="0.03 0.03 0.36"/>
            </geometry>
            <material name="red"/>
            <origin xyz="0 0 -0.18" rpy="0 0 0"/>
        </visual>
    </link>

    <link name="r_rod_4">
        <visual>
            <geometry>
                <box size="0.03 0.03 0.36"/>
            </geometry>
            <material name="red"/>
            <origin xyz="0 0 -0.18" rpy="0 0 0"/>
        </visual>
    </link>
    
    <link name="left_steer_link1" />
    <link name="right_steer_link1" />


    <link name="left_wheel1">
        <visual>
            <geometry>
                <cylinder radius="0.078" length="0.075"/>
            </geometry>
            <origin xyz="0 0 0.0525" rpy="0 0 0"/>
            <material name="white"/>
        </visual>
    </link>

    <link name="left_wheel2">
        <visual>
            <geometry>
                <cylinder radius="0.078" length="0.075"/>
            </geometry>
            <origin xyz="0 0 0.0525" rpy="0 0 0"/>
            <material name="white"/>
        </visual>
    </link>

    <link name="left_wheel3">
        <visual>
            <geometry>
                <cylinder radius="0.078" length="0.075"/>
            </geometry>
            <origin xyz="0 0 0.0525" rpy="0 0 0"/>
            <material name="white"/>
        </visual>
    </link>

    <link name="right_wheel1">
        <visual>
            <geometry>
                <cylinder radius="0.078" length="0.075"/>
            </geometry>
            <origin xyz="0 0 0.0525" rpy="0 0 0"/>
            <material name="white"/>
        </visual>
    </link>

    <link name="right_wheel2">
        <visual>
            <geometry>
                <cylinder radius="0.078" length="0.075"/>
            </geometry>
            <origin xyz="0 0 0.0525" rpy="0 0 0"/>
            <material name="white"/>
        </visual>
    </link>

    <link name="right_wheel3">
        <visual>
            <geometry>
                <cylinder radius="0.078" length="0.075"/>
            </geometry>
            <origin xyz="0 0 0.0525" rpy="0 0 0"/>
            <material name="white"/>
        </visual>
    </link>
    
    <joint name="left_diff_joint" type="fixed">
        <parent link="base_link"/>
        <child link="left_diff_link"/>
        <axis xyz="0 0 1"/> 
        <origin rpy="-${pi/2} 0 0" xyz="0 0.215 0"/> 
        <limit lower="-3.14" upper="3.14" effort="10" velocity="1"/>
    </joint>

    <joint name="right_diff_joint" type="fixed">
        <parent link="base_link"/>
        <child link="right_diff_link"/>
        <axis xyz="0 0 1"/> 
        <origin rpy="-${pi/2} 0 0" xyz="0 -0.215 0"/> 
        <limit lower="-3.14" upper="3.14" effort="10" velocity="1"/>
    </joint>
    

    <joint name="left_diff_rod1" type="fixed">
        <parent link="left_diff_link"/>
        <child link="l_rod_1"/>
        <axis xyz="0 0 1"/> 
        <origin rpy="${pi/2} 0 -0.895" xyz="0 0 0"/> 
    </joint>

    <joint name="right_diff_rod1" type="fixed">
        <parent link="right_diff_link"/>
        <child link="r_rod_1"/>
        <axis xyz="0 0 1"/> 
        <origin rpy="${pi/2} 0 -0.895" xyz="0 0 0"/> 
    </joint>

    <joint name="left_diff_rod2" type="fixed">
        <parent link="left_diff_link"/>
        <child link="l_rod_2"/>
        <axis xyz="0 0 1"/> 
        <origin rpy="${pi/2} 0 0.785" xyz="0 0 0"/> 
    </joint>

    <joint name="right_diff_rod2" type="fixed">
        <parent link="right_diff_link"/>
        <child link="r_rod_2"/>
        <axis xyz="0 0 1"/> 
        <origin rpy="${pi/2} 0 0.785" xyz="0 0 0"/> 
    </joint>

    <joint name="left_rod2_sub_joint" type="fixed">
        <parent link="l_rod_2"/>
        <child link="left_rod2_sub_link"/>
        <axis xyz="0 0 1"/> 
        <origin rpy="-${pi/2} 0 0" xyz="0 0 -0.28"/> 
        <limit lower="-3.14" upper="3.14" effort="10" velocity="1"/>
    </joint>

    <joint name="right_rod2_sub_joint" type="fixed">
        <parent link="r_rod_2"/>
        <child link="right_rod2_sub_link"/>
        <axis xyz="0 0 1"/> 
        <origin rpy="-${pi/2} 0 0" xyz="0 0 -0.28"/> 
        <limit lower="-3.14" upper="3.14" effort="10" velocity="1"/>
    </joint>


    <joint name="left_rod2_sub_rod1_joint" type="fixed">
        <parent link="left_rod2_sub_link"/>
        <child link="l_rod_3"/>
        <origin rpy="${pi/2} 0 0" xyz="0 0 0"/> 
    </joint> 

    <joint name="right_rod2_sub_rod1_joint" type="fixed">
        <parent link="right_rod2_sub_link"/>
        <child link="r_rod_3"/>
        <origin rpy="${pi/2} 0 0" xyz="0 0 0"/> 
    </joint> 

     <joint name="left_rod2_sub_rod2_joint" type="fixed">
        <parent link="left_rod2_sub_link"/>
        <child link="l_rod_4"/>
        <origin rpy="${pi/2} 0 -1.588" xyz="0 0 0"/>  
    </joint> 

    <joint name="right_rod2_sub_rod2_joint" type="fixed">
        <parent link="right_rod2_sub_link"/>
        <child link="r_rod_4"/>
        <origin rpy="${pi/2} 0 -1.588" xyz="0 0 0"/>  
    </joint> 


     <joint name="rear_left_wheel_joint" type="continuous">
         <parent link="l_rod_3"/>
        <child link="left_wheel2"/>
        <axis xyz="0 0 1"/> 
        <origin rpy="-${pi/2} 0 0" xyz="0  0 -0.358"   />  

   </joint>

   <joint name="rear_right_wheel_joint" type="continuous">
         <parent link="r_rod_3"/>
        <child link="right_wheel2"/>
        <axis xyz="0 0 1"/> 
        <origin rpy="${pi/2} 0 0" xyz="0  0 -0.358"   />  

   </joint>

       <joint name="middle_left_wheel_joint" type="continuous">
         <parent link="l_rod_4"/>
        <child link="left_wheel3"/>
        <axis xyz="0 0 1"/> 
        <origin rpy="-${pi/2} 0 0" xyz="0  0 -0.358"/>  

   </joint>

   <joint name="middle_right_wheel_joint" type="continuous">
         <parent link="r_rod_4"/>
        <child link="right_wheel3"/>
        <axis xyz="0 0 1"/> 
        <origin rpy="${pi/2} 0 0" xyz="0  0 -0.358"/>  

   </joint>

   <joint name="left_steer_joint1" type="fixed">
        <parent link="l_rod_1"/>
        <child link="left_steer_link1"/>
        <axis xyz="0 0 1"/> 
        <origin xyz="0 0 -0.64" rpy="0 0 0"/>
        <limit lower="-0.785" upper="0.785" effort="10" velocity="1"/>
   </joint>

   <joint name="right_steer_joint1" type="fixed">
        <parent link="r_rod_1"/>
        <child link="right_steer_link1"/>
        <axis xyz="0 0 1"/> 
        <origin xyz="0 0 -0.64" rpy="0 0 0"/>
        <limit lower="-0.785" upper="0.785" effort="10" velocity="1"/>
   </joint>

   <joint name="front_left_wheel_joint" type="continuous">
        <parent link="left_steer_link1"/>
        <child link="left_wheel1"/>
        <axis xyz="1 0 0"/> 
        <origin xyz="0 0 0" rpy="-${pi/2} 0 0"/>
   </joint>

   <joint name="front_right_wheel_joint" type="continuous">
        <parent link="right_steer_link1"/>
        <child link="right_wheel1"/>
        <axis xyz="1 0 0"/> 
        <origin xyz="0 0 0" rpy="${pi/2} 0 0"/>
   </joint>

     <joint name="laser_joint" type="fixed">
        <parent link="base_link"/>
        <child link="laser_frame"/>
        <origin xyz="0.122 0 0.212" rpy="0 0 0"/>
    </joint>

    <link name="laser_frame">
        <visual>
            <geometry>
                <cylinder radius="0.05" length="0.04"/>
            </geometry>
            <material name="black"/>
        </visual>
        <visual>
            <origin xyz="0 0 -0.05"/>
            <geometry>
                <cylinder radius="0.01" length="0.1"/>
            </geometry>
            <material name="black"/>
        </visual>
        <collision>
            <geometry>
                <cylinder radius="0.05" length="0.04"/>
            </geometry>
        </collision>
        <xacro:inertial_cylinder mass="0.1" length="0.04" radius="0.05">
            <origin xyz="0 0 0" rpy="0 0 0"/>
        </xacro:inertial_cylinder>
    </link>

    <joint name="camera_joint" type="fixed">
        <parent link="base_link"/>
        <child link="camera_link"/>
        <origin xyz="0.305 0 0.08" rpy="0 0 0"/>
    </joint>

    <link name="camera_link">
        <visual>
            <geometry>
                <box size="0.025 0.12 0.03"/>
            </geometry>
            <material name="red"/>
        </visual>
    </link>

        <joint name="antenna_joint" type="fixed">
        <parent link="base_link"/>
        <child link="antenna_link"/>
        <origin xyz="-0.305 0 0" rpy="0 0 0"/>
    </joint>

    <link name="antenna_link">
        <visual>
            <geometry>
                 <cylinder radius="0.015" length="0.6"/>
            </geometry>
            <origin xyz="0 0 0.3" rpy="0 0 0"/>
            <material name="red"/>
        </visual>
    </link>



</robot>